#VRML_SIM R2023b utf8

EXTERNPROTO "https://raw.githubusercontent.com/cyberbotics/webots/R2023b/projects/objects/backgrounds/protos/TexturedBackground.proto"
EXTERNPROTO "https://raw.githubusercontent.com/cyberbotics/webots/R2023b/projects/objects/backgrounds/protos/TexturedBackgroundLight.proto"
EXTERNPROTO "https://raw.githubusercontent.com/cyberbotics/webots/R2023b/projects/objects/floors/protos/RectangleArena.proto"

WorldInfo {
}
Viewpoint {
  orientation 0.14881804911288535 0.18398174707478748 -0.9715986336968285 1.341718829285616
  position -4.455044520977497 -0.08468560389724192 0.4854036899127734
}
TexturedBackground {
}
TexturedBackgroundLight {
}
RectangleArena {
  translation 0 0 -0.16
  floorSize 10 10
}
Robot {
  translation -4.077493211067156 -1.282252971101993 -0.1202678458812962
  rotation 0.6143911516537146 -0.5579293325983694 -0.5578874192845364 2.0404167871259196
  children [
    Display {
      translation 0 0.08 0
    }
    Solid {
      translation 0 0.035 0.07
      children [
        Camera {
          translation 0 0 0.03
          rotation 0.5773509358560258 0.577349935856137 0.577349935856137 -2.094395307179586
        }
        Shape {
          appearance PBRAppearance {
          }
          geometry Box {
            size 0.02 0.02 0.05
          }
        }
      ]
      name "solid(4)"
    }
    HingeJoint {
      jointParameters HingeJointParameters {
        position 493.3412060909305
        anchor 0.05999999859394789 8.606224709772903e-06 0.04999999869043026
      }
      device [
        RotationalMotor {
          name "motor_1"
        }
      ]
      endPoint Solid {
        translation 0.05999999999999957 1.321015872022877e-05 0.05000051125611666
        rotation 0.7065605628653941 0.0393108978914062 -0.7065598518953007 3.220174404668129
        children [
          DEF Wheel Shape {
            appearance PBRAppearance {
            }
            geometry Cylinder {
              height 0.02
              radius 0.04
            }
          }
        ]
        name "solid(3)"
        boundingObject USE Wheel
        physics DEF Physics_wh Physics {
        }
        linearVelocity 1.524055525350781e-07 1.4725460822784808e-08 2.4113815393197576e-07
        angularVelocity -3.690417911115169e-07 3.82083608325816e-06 -1.9503164977197283e-10
      }
    }
    HingeJoint {
      jointParameters HingeJointParameters {
        position 467.7403583673154
        anchor -0.05999999937392844 6.956743753339101e-06 0.049999897664519954
      }
      device [
        RotationalMotor {
          name "motor_2"
        }
      ]
      endPoint Solid {
        translation -0.05999999999999972 1.030160841053468e-05 0.04999864780043924
        rotation 0.7014221482585585 0.12653205740194892 0.7014246990105057 2.8898674552564656
        children [
          DEF Wheel Shape {
            appearance PBRAppearance {
            }
            geometry Cylinder {
              height 0.02
              radius 0.04
            }
          }
        ]
        name "solid(2)"
        boundingObject USE Wheel
        physics Physics {
        }
        linearVelocity 1.5349470184371315e-07 1.4831619146763377e-08 2.3171818116088796e-07
        angularVelocity -3.690462258983106e-07 3.8208817799538855e-06 -1.9500888377780888e-10
      }
    }
    HingeJoint {
      jointParameters HingeJointParameters {
        position 467.74037017084845
        anchor -0.05999988563290504 -7.99438004961961e-05 -0.05000005917449002
      }
      device [
        RotationalMotor {
          name "motor_3"
        }
      ]
      endPoint Solid {
        translation -0.05999988411462047 -7.558461391687561e-05 -0.050001687125235436
        rotation 0.7014241811216101 0.12652744378830896 0.7014234983989879 2.889874734637193
        children [
          DEF Wheel Shape {
            appearance PBRAppearance {
            }
            geometry Cylinder {
              height 0.02
              radius 0.04
            }
          }
        ]
        name "solid(1)"
        boundingObject USE Wheel
        physics Physics {
        }
        linearVelocity 1.521608002287617e-07 1.4690588409723646e-08 -1.3513457767601392e-07
        angularVelocity -3.690339741003459e-07 3.820759143519428e-06 -1.9505944105628078e-10
      }
    }
    DEF solid1 HingeJoint {
      jointParameters HingeJointParameters {
        position 467.7403821495896
        anchor 0.059999998601311735 3.8007432466014013e-06 -0.05000000073172495
      }
      device [
        RotationalMotor {
          name "motor_4"
        }
      ]
      endPoint Solid {
        translation 0.05999999999999851 7.361693768313785e-06 -0.050001329370556166
        rotation 0.7014245718873334 -0.12652329113095984 -0.7014238567043904 2.8898832633201357
        children [
          DEF Wheel Shape {
            appearance PBRAppearance {
            }
            geometry Cylinder {
              height 0.02
              radius 0.04
            }
          }
        ]
        boundingObject USE Wheel
        physics DEF Physics_wh Physics {
        }
        linearVelocity 1.5328108938446652e-07 1.4799796254597889e-08 -1.44692140394454e-07
        angularVelocity -3.690440139171924e-07 3.820863134691037e-06 -1.9501949617043822e-10
      }
    }
    DEF Body Shape {
      appearance PBRAppearance {
        baseColor 0 1 0
        metalness 0
      }
      geometry Box {
        size 0.1 0.05 0.2
      }
    }
  ]
  boundingObject USE Body
  physics Physics {
  }
  controller "drive_my_robot"
  window "generic_window"
  remoteControl ""
  linearVelocity 1.575900956571875e-07 1.521921151830247e-08 8.229246251919845e-10
  angularVelocity -3.690360842619193e-07 3.820857191621103e-06 -1.9369635841098421e-10
}
